Workbook

Sheet 分类
A1: 类别 | B1: 周 | C1: 计数 | D1: 描述 | F1: 最新克隆日期：2026.7.17
A2: 涂黑I | B2: 1 | C2: ==COUNTIF(题型与规则!F4:F1035,B2) -> 31 | D2: 一种颜色连通成一个整体
A3: 涂黑II | B3: 2 | C3: ==COUNTIF(题型与规则!F5:F1036,B3) -> 34 | D3: 单个色块是某种形状，或黑白规则交替 | F3: Eric Fox的英文规则词典 | I3: 比较全的英文规则文本
A4: 放置/涂黑III | B4: 3 | C4: ==COUNTIF(题型与规则!F6:F1037,B4) -> 30 | D4: 多个黑色块间有某种关系，或放置类题型 | F4: yyao的谜题分类学 | I4: 将题型按规则相似程度分类
A5: 填写 | B5: 4 | C5: ==COUNTIF(题型与规则!F7:F1038,B5) -> 37 | D5: 填入几种符号之一 | F5: WPC unofficial wiki | I5: 记载了一些题型最初在哪里出现
A6: 分区 | B6: 5 | C6: ==COUNTIF(题型与规则!F8:F1039,B6) -> 33 | D6: 解法是描边界
A7: 回路I/路径I | B7: 6 | C7: ==COUNTIF(题型与规则!F9:F1040,B7) -> 42 | D7: 回路不经过的空格没有任何限制 | F7: puzz.link的题型列表
A8: 回路II/路径II | B8: 7 | C8: ==COUNTIF(题型与规则!F10:F1041,B8) -> 29 | D8: 回路经过所有空格，或者回路不经过的空格也有规则限制 | F8: pzprxs.vercel.app的题型列表
B9: 目前共收录 | C9: ==SUM(C2:C8) -> 236 | D9: 种纸笔谜题
B10: 规则文本共 | C10: ==SUM(题型与规则!J4:J1048576) -> 19992 | D10: 字 | F10: November的GAPP规则译文 | I10: 有些规则会在校对后录入本表
A12: 这是北京大学谜题协会【每日谜题】纸笔推荐文案模板【分类与规则】部分的一个克隆。 | H12: 本表远非详尽无遗，
A13: 本文档旨在收集并总结来源较为权威的纸笔谜题规则的【中文译文】。 | H13: 欢迎任何形式的补充、勘误、建议：
A14: 中文规则的文本来源如下： | H14: QQ 2418286836 (@COL)
B15: - World Puzzle Championship 2024的中文规则手册，经World Puzzle Federation许可使用 | H15: 欢迎加入北大谜协每日纸笔推荐组：
B16: - 笔者翻译自Eric Fox的英文规则词典 | H16: QQ 1056908122
B17: - 其他来源（特别注明） | H17: 我们在这里为题目定时，推荐纸笔题目，讨论规则文本
A18: 考虑北大谜协【每日谜题】的举办方式与受众，我们进行了如下调整：
B19: - 只收录有盘面的题型。不轻易收录无法在puzzlink上作答的题型。不收录变种(不能被puzzlink判定答案的)题型。
B20: - 调整规则叙述以适应puzzlink的作答界面。
B21: - 在类别划分上，将所有题型划分为 7 个题型数量大致相等的类别，每周在 7 种类别中循环。
B22: - 在题目的类别归属上，优先选择浅显的理解方式（例如Cave在涂黑类）。
B23: - 为了尽可能缩短长度，对规则表述有一定删减（例如删除“有一些数字可能已经填入了盘面中”）
A24: 请注意以上调整可能不完全符合所有纸笔爱好者的需求。

Sheet 题型与规则
A1: ref name | B1: pzplus | C1: Name (en) | E1: Name (zh) | F1: Day | G1: Type | I1: Rules | J1: Length | K1: Rule Source | L1: Etymology (jp en) | M1: Origin | N1: Year | O1: Ref
A2: pzplus名称 | B2: 收录? | C2: 英文名 | E2: 中文名 | F2: 周 | G2: 分类 | I2: 规则 | J2: 字数 | K2: 规则文本来源 | L2: 命名缘由（日 英） | M2: 来源 | N2: 年份 | O2: 参考资料
A3: 1 | B3: 2 | C3: 3 | D3: 4 | E3: 5 | F3: 6 | G3: 7 | I3: 9 | J3: 10 | K3: 11 | L3: 12 | M3: 13 | N3: 14 | O3: 15
A4: creek | B4: 1 | C4: Creek | D4: 溪流 | E4: ==HYPERLINK(_xlfn.CONCAT("pzplus.tck.mn/db?type=",A4,"&variant=no"),IF(D4<>0,D4,A4)) -> 溪流 | F4: 1 | G4: 涂黑I | H4: 颜色正交连通 | I4: 涂黑一些格子，使得留白的格子连通成一个整体。圆圈里的数字表示接触此顶点的涂黑格数。 | J4: ==IF(LEN(I4)>0,LEN(I4),"") -> 41 | K4: WPC2024IB | L4: / | M4: Nikoli vol. 110 | N4: 2005 | O4: PC, Nikoli
A5: disco | B5: 0.8 | C5: Disconnection | E5: ==HYPERLINK(_xlfn.CONCAT("pzplus.tck.mn/db?type=",A5,"&variant=no"),IF(D5<>0,D5,A5)) -> disco | F5: 1 | G5: 涂黑I | H5: 颜色正交连通 | I5: 在每个区域内涂黑恰好两组连通的格子，使得所有涂黑的格子连通成一个整体，且没有全部涂黑的2×2结构。 | J5: ==IF(LEN(I5)>0,LEN(I5),"") -> 49 | K5: Sigmit64 | L5: / | M5: Inaba Naoki | O5: puzzlink
A6: hitori | B6: 1 | C6: Hitori | D6: 数壹 | E6: ==HYPERLINK(_xlfn.CONCAT("pzplus.tck.mn/db?type=",A6,"&variant=no"),IF(D6<>0,D6,A6)) -> 数壹 | F6: 1 | G6: 涂黑I | H6: 颜色正交连通 | I6: 涂黑一些格子，使得涂黑的格子之间不相邻，且留白的格子连通成一个整体。任意两个同行或同列的留白格不能包含相同的数字。 | J6: ==IF(LEN(I6)>0,LEN(I6),"") -> 57 | K6: WPC2024IB | L6: ひとり(=独自) | M6: Nikoli vol. 29 | N6: 1990 | O6: PC, Nikoli
A7: lits | B7: 1 | C7: LITS | D7: 四格骨墙 | E7: ==HYPERLINK(_xlfn.CONCAT("pzplus.tck.mn/db?type=",A7,"&variant=no"),IF(D7<>0,D7,A7)) -> 四格骨墙 | F7: 1 | G7: 涂黑I | H7: 颜色正交连通 | I7: 在每个区域内涂黑一个四格骨牌，使得所有涂黑的格子连通成一个整体，且没有全部涂黑的2×2结构。不同区域中全等的四格骨牌不能相邻。 | J7: ==IF(LEN(I7)>0,LEN(I7),"") -> 63 | K7: WPC2024IB | L7: 四格骨牌象形 | M7: Nikoli | N7: 2004 | O7: PC
A8: aqre | B8: 1 | C8: Aqre | D8: 黑白无四 | E8: ==HYPERLINK(_xlfn.CONCAT("pzplus.tck.mn/db?type=",A8,"&variant=no"),IF(D8<>0,D8,A8)) -> 黑白无四 | F8: 1 | G8: 涂黑I | H8: 颜色正交连通 | I8: 涂黑一些空格，使得所有涂黑的格子连通成一个整体，且没有全部涂黑或者全部留白的1×4或4×1的结构。数字表示此区域内涂黑格的个数。 | J8: ==IF(LEN(I8)>0,LEN(I8),"") -> 64 | K8: WPC2024IB | L8: acre+字母q | M8: Eric Fox | N8: 2020 | O8: PC
A9: parquet | B9: 1 | C9: Parquet | D9: 拼花地板 | E9: ==HYPERLINK(_xlfn.CONCAT("pzplus.tck.mn/db?type=",A9,"&variant=no"),IF(D9<>0,D9,A9)) -> 拼花地板 | F9: 1 | G9: 涂黑I | H9: 颜色正交连通 | I9: 在每个粗线构成的区域内完全涂黑恰好一个被细线分隔的区域，使得所有涂黑的格子连通成一个整体。涂黑格不能形成回路（包括2×2结构）。 | J9: ==IF(LEN(I9)>0,LEN(I9),"") -> 64 | K9: dodomos | L9: /
A10: nothree | B10: 1 | C10: No Three | D10: 等隔无三 | E10: ==HYPERLINK(_xlfn.CONCAT("pzplus.tck.mn/db?type=",A10,"&variant=no"),IF(D10<>0,D10,A10)) -> 等隔无三 | F10: 1 | G10: 涂黑I | H10: 颜色正交连通 | I10: 涂黑一些格子，使得涂黑的格子之间不相邻，且留白的格子连通成一个整体。每个圆圈恰和一个涂黑格接触。同一行或同一列的三个连续黑格不能等距排列。 | J10: ==IF(LEN(I10)>0,LEN(I10),"") -> 69 | K10: COL译自Eric Fox | L10: / | M10: Nikoli vol. 158 | N10: 2017 | O10: Nikoli
A11: teri | B11: 1 | C11: Territory | D11: 矩形领土 | E11: ==HYPERLINK(_xlfn.CONCAT("pzplus.tck.mn/db?type=",A11,"&variant=no"),IF(D11<>0,D11,A11)) -> 矩形领土 | F11: 1 | G11: 涂黑I | H11: 颜色正交连通 | I11: 涂黑一些格子，使得涂黑的格子之间不相邻，且留白的格子连通成一个整体。有白圈的格子必须留白。白圈里的数字表示包含此格的最大留白长方形的面积。 | J11: ==IF(LEN(I11)>0,LEN(I11),"") -> 69 | K11: COL译自puzzlink | L11: / | M11: Inaba Naoki | N11: not in src | O11: PC
A12: heyawake | B12: 1 | C12: Heyawake | D12: 数间 | E12: ==HYPERLINK(_xlfn.CONCAT("pzplus.tck.mn/db?type=",A12,"&variant=no"),IF(D12<>0,D12,A12)) -> 数间 | F12: 1 | G12: 涂黑I | H12: 颜色正交连通 | I12: 涂黑一些格子，使得涂黑的格子之间不相邻，且留白的格子连通成一个整体。任意一横段或纵段留白格不能穿过两个以上区域边界。数字表示此区域内涂黑格的个数。 | J12: ==IF(LEN(I12)>0,LEN(I12),"") -> 73 | K12: WPC2024IB | L12: 部屋分け | M12: Nikoli vol. 39 | N12: 1992 | O12: PC, Nikoli
A13: nurikabe | B13: 1 | C13: Nurikabe | D13: 数墙 | E13: ==HYPERLINK(_xlfn.CONCAT("pzplus.tck.mn/db?type=",A13,"&variant=no"),IF(D13<>0,D13,A13)) -> 数墙 | F13: 1 | G13: 涂黑I | H13: 颜色正交连通 | I13: 涂黑一些空格，使得所有涂黑的格子连通成一个整体，且没有全部涂黑的2×2结构。每一组连通的留白格必须恰好包含一个数字。数字表示其所在的留白的连通组格数。 | J13: ==IF(LEN(I13)>0,LEN(I13),"") -> 75 | K13: WPC2024IB | L13: 塗壁 | M13: Nikoli vol. 33 | N13: 1991 | O13: PC, Nikoli
A14: akichi | B14: 1 | C14: Akichiwake | D14: 数间(空地) | E14: ==HYPERLINK(_xlfn.CONCAT("pzplus.tck.mn/db?type=",A14,"&variant=no"),IF(D14<>0,D14,A14)) -> 数间(空地) | F14: 1 | G14: 涂黑I | H14: 颜色正交连通 | I14: 涂黑一些格子，使得涂黑的格子之间不相邻，且留白的格子连通成一个整体。任意一横段或纵段留白格不能穿过两个以上区域边界。数字表示此区域内最大留白连通组的面积。 | J14: ==IF(LEN(I14)>0,LEN(I14),"") -> 77 | K14: 改自Heyawake | L14: 空き地+heyawake | M14: Prasanna Seshadri | N14: not in src | O14: PC
A15: canal | B15: 1 | C15: Canal View | D15: 峡谷 | E15: ==HYPERLINK(_xlfn.CONCAT("pzplus.tck.mn/db?type=",A15,"&variant=no"),IF(D15<>0,D15,A15)) -> 峡谷 | F15: 1 | G15: 涂黑I | H15: 颜色正交连通 | I15: 涂黑一些空格，使得所有涂黑的格子连通成一个整体，且没有全部涂黑的2×2结构。圆圈里的数字表示此格横竖能够直接连接到且不被留白格阻挡的涂黑格个数，不包括此格本身。 | J15: ==IF(LEN(I15)>0,LEN(I15),"") -> 80 | K15: WPC2024IB | L15: / | M15: Prasanna Seshadri | N15: 2014 | O15: PC
A16: sumiwake | B16: 0.8 | C16: Sumiwake | D16: 圆角房间 | E16: ==HYPERLINK(_xlfn.CONCAT("pzplus.tck.mn/db?type=",A16,"&variant=no"),IF(D16<>0,D16,A16)) -> 圆角房间 | F16: 1 | G16: 涂黑I | H16: 颜色正交连通 | I16: 涂黑一些格子，使得涂黑的格子之间不相邻，且留白的格子连通成一个整体。任意一横段或纵段留白格不能穿过两个以上区域边界。白圈恰和一个涂黑格接触，黑圈恰和两个涂黑格接触。 | J16: ==IF(LEN(I16)>0,LEN(I16),"") -> 82 | K16: COL译自puzzlink | L16: 隅+heyawake | M16: Nikoli vol. 66 | N16: 1997 | O16: Nikoli
A17: usoone | B17: 1 | C17: Uso-One | D17: 单一谎言 | E17: ==HYPERLINK(_xlfn.CONCAT("pzplus.tck.mn/db?type=",A17,"&variant=no"),IF(D17<>0,D17,A17)) -> 单一谎言 | F17: 1 | G17: 涂黑I | H17: 颜色正交连通 | I17: 涂黑一些格子，使得涂黑的格子之间不相邻，且留白的格子连通成一个整体。数字表示与之相邻的（至多）四格中涂黑格的个数。数字格不能涂黑。每个区域内都恰好有一个错误的数字。 | J17: ==IF(LEN(I17)>0,LEN(I17),"") -> 82 | K17: dodomos, 有修改 | L17: 嘘+one | M17: Nikoli vol. 151 | N17: 2015 | O17: Nikoli
A18: yajikazu | B18: 1 | C18: Yajisan-Kazusan | D18: 真假仙人 | E18: ==HYPERLINK(_xlfn.CONCAT("pzplus.tck.mn/db?type=",A18,"&variant=no"),IF(D18<>0,D18,A18)) -> 真假仙人 | F18: 1 | G18: 涂黑I | H18: 颜色正交连通 | I18: 涂黑一些格子，使得涂黑的格子之间不相邻，且留白的格子连通成一个整体。在留白格内有箭头的数字表示从此格开始在这个方向中涂黑格的个数。这些提示数在涂黑格里则不提供信息。 | J18: ==IF(LEN(I18)>0,LEN(I18),"") -> 82 | K18: WPC2024IB | L18: 缩略自 矢印さん+数さん | M18: Nikoli vol. 74 | N18: 1998 | O18: PC, Nikoli
A19: kurodoko | B19: 1 | C19: Kurodoko | D19: 田鼠挖洞 | E19: ==HYPERLINK(_xlfn.CONCAT("pzplus.tck.mn/db?type=",A19,"&variant=no"),IF(D19<>0,D19,A19)) -> 田鼠挖洞 | F19: 1 | G19: 涂黑I | H19: 颜色正交连通 | I19: 涂黑一些格子，使得涂黑的格子之间不相邻，且留白的格子连通成一个整体。白圈里的数字必须在留白格里，并表示此格横竖能够直接连接到且不被涂黑格阻挡的留白格个数，包括此格本身。 | J19: ==IF(LEN(I19)>0,LEN(I19),"") -> 84 | K19: WPC2024IB | L19: 缩略自 黒マスはどこだ | M19: Nikoli vol. 34 | N19: 1991 | O19: PC, Nikoli
A20: paintarea | B20: 1 | C20: Paintarea | D20: 涂鸦区域 | E20: ==HYPERLINK(_xlfn.CONCAT("pzplus.tck.mn/db?type=",A20,"&variant=no"),IF(D20<>0,D20,A20)) -> 涂鸦区域 | F20: 1 | G20: 涂黑I | H20: 颜色正交连通 | I20: 涂黑一些格子，使得所有涂黑的格子连通成一个整体，且没有全部涂黑或者全部留白的2×2结构。每个区域要么全部涂黑要么全部留白。数字表示与之相邻的（至多）四格中涂黑格的个数。 | J20: ==IF(LEN(I20)>0,LEN(I20),"") -> 84 | K20: dodomos | L20: paint+area | M20: Nikoli vol. 69 | N20: 1997 | O20: Nikoli
A21: nuritwin | B21: 0.8 | C21: Nuritwin | D21: 涂黑成对 | E21: ==HYPERLINK(_xlfn.CONCAT("pzplus.tck.mn/db?type=",A21,"&variant=no"),IF(D21<>0,D21,A21)) -> 涂黑成对 | F21: 1 | G21: 涂黑I | H21: 颜色正交连通 | I21: 在每个区域内涂黑恰好两组连通的格子，使得这两组格子面积相等且不相邻，且所有涂黑的格子连通成一个整体。不能有全部涂黑的2×2结构。数字表示其所在区域内一个涂黑格连通组的面积。 | J21: ==IF(LEN(I21)>0,LEN(I21),"") -> 86 | K21: Sigmit64, COL | L21: 塗り+twin | M21: Nikoli vol. 186 | N21: 2024 | O21: puzzlink
A22: aquapelago | B22: 1 | C22: Aquapelago | D22: 千岛湖 | E22: ==HYPERLINK(_xlfn.CONCAT("pzplus.tck.mn/db?type=",A22,"&variant=no"),IF(D22<>0,D22,A22)) -> 千岛湖 | F22: 1 | G22: 涂黑I | H22: 颜色正交连通 | I22: 涂黑一些格子，使得涂黑的格子之间不相邻，且留白的格子连通成一个整体。不能有全部留白的2×2结构。数字所在的格子必须涂黑。数字表示其所在的对角连通的一组涂黑格的格数，包括格子本身。 | J22: ==IF(LEN(I22)>0,LEN(I22),"") -> 89 | K22: WPC2024IB | L22: aqua+archipelago | M22: Walker Anderson | N22: 2023 | O22: PC
A23: context | B23: 1 | C23: Context | D23: 黑斜白邻 | E23: ==HYPERLINK(_xlfn.CONCAT("pzplus.tck.mn/db?type=",A23,"&variant=no"),IF(D23<>0,D23,A23)) -> 黑斜白邻 | F23: 1 | G23: 涂黑I | H23: 颜色正交连通 | I23: 涂黑一些格子，使得涂黑的格子之间不相邻，且留白的格子连通成一个整体。在留白格内的数字表示和此格相邻的涂黑格的个数。这些提示数在涂黑格里则表示和此格接触（但不相邻）的涂黑格的个数。 | J23: ==IF(LEN(I23)>0,LEN(I23),"") -> 89 | K23: WPC2024IB, 有删改 | L23: / | M23: RSP | N23: 2022 | O23: PC
A24: cave | B24: 1 | C24: Cave | D24: 山洞 | E24: ==HYPERLINK(_xlfn.CONCAT("pzplus.tck.mn/db?type=",A24,"&variant=no"),IF(D24<>0,D24,A24)) -> 山洞 | F24: 1 | G24: 涂黑I | H24: 颜色正交连通 | I24: 涂黑一些格子，使得所有涂黑的格子都能沿涂黑格横竖连通到盘面边界，且留白的格子连通成一个整体。数字必须在留白格里，并表示此格横竖能够直接连接到且不被涂黑格阻挡的留白格个数，包括此格本身。 | J24: ==IF(LEN(I24)>0,LEN(I24),"") -> 92 | K24: 改自Kurodoko | L24: / | M24: Nikoli vol. 60 | N24: 1996 | O24: PC, Nikoli
A25: guidearrow | B25: 1 | C25: Guide Arrow | D25: 指引箭头 | E25: ==HYPERLINK(_xlfn.CONCAT("pzplus.tck.mn/db?type=",A25,"&variant=no"),IF(D25<>0,D25,A25)) -> 指引箭头 | F25: 1 | G25: 涂黑I | H25: 颜色正交连通 | I25: 涂黑一些格子，使得涂黑的格子之间不相邻，且留白的格子连通成一个整体。留白格不能形成回路（包括2×2结构）。箭头表示从此格出发，在不经过涂黑格也不倒退的情况下，能够走到星星的路径的唯一方向。 | J25: ==IF(LEN(I25)>0,LEN(I25),"") -> 94 | K25: COL译自Eric Fox | L25: / | M25: Inaba Naoki | N25: 2004 | O25: PC
A26: ayeheya | B26: 1 | C26: Ayeheya | D26: 对称数间 | E26: ==HYPERLINK(_xlfn.CONCAT("pzplus.tck.mn/db?type=",A26,"&variant=no"),IF(D26<>0,D26,A26)) -> 对称数间 | F26: 1 | G26: 涂黑I | H26: 颜色正交连通 | I26: 涂黑一些格子，使得涂黑的格子之间不相邻，且留白的格子连通成一个整体。任意一横段或纵段留白格不能穿过两个以上区域边界。数字表示此区域内涂黑格的个数。所有区域的涂黑情况必须满足180°旋转对称。 | J26: ==IF(LEN(I26)>0,LEN(I26),"") -> 95 | K26: 见Heyawake, 增加一句 | L26: Heyawake写作回文
A27: oasis | B27: 0.8 | C27: Oasis | D27: 绿洲 | E27: ==HYPERLINK(_xlfn.CONCAT("pzplus.tck.mn/db?type=",A27,"&variant=no"),IF(D27<>0,D27,A27)) -> 绿洲 | F27: 1 | G27: 涂黑I | H27: 颜色正交连通 | I27: 涂黑一些格子，使得涂黑的格子之间不相邻，且留白的格子连通成一个整体。不能有全部留白的2×2结构。有白圈的格子必须留白。白圈里的数字表示从此格出发，在只经过空白格的情况下，可以走到的白圈个数。 | J27: ==IF(LEN(I27)>0,LEN(I27),"") -> 95 | K27: November, 有修改 | L27: / | M27: Matej Uher | N27: 2016 | O27: PC
A28: nurimisaki | B28: 1 | C28: Nurimisaki | D28: 数岬 | E28: ==HYPERLINK(_xlfn.CONCAT("pzplus.tck.mn/db?type=",A28,"&variant=no"),IF(D28<>0,D28,A28)) -> 数岬 | F28: 1 | G28: 涂黑I | H28: 颜色正交连通 | I28: 涂黑一些空格，使得所有留白的格子连通成一个整体，且没有全部涂黑或者全部留白的2×2结构。圆圈标记了所有恰好只和另一个留白格相邻的留白格。圆圈里的数字表示此格横竖能够直接连接到且不被涂黑格阻挡的留白格个数，包括此格本身。 | J28: ==IF(LEN(I28)>0,LEN(I28),"") -> 109 | K28: WPC2024IB | L28: 塗り+岬 | M28: Nikoli vol. 163 | N28: 2018 | O28: PC, janko
A29: sashikabe | B29: 0.8 | C29: Sashikabe | D29: 曲尺数墙 | E29: ==HYPERLINK(_xlfn.CONCAT("pzplus.tck.mn/db?type=",A29,"&variant=no"),IF(D29<>0,D29,A29)) -> 曲尺数墙 | F29: 1 | G29: 涂黑I | H29: 颜色正交连通 | I29: 涂黑一些空格，使得所有涂黑的格子连通成一个整体，且没有全部涂黑的2×2结构。每一组连通的留白格必须是宽度为一的L形区域。圆圈必须在L形留白区域内转弯的位置，而箭头则必须在留白区域的一端，指向转弯的位置。圆圈里的数字表示其所在留白区域的面积。 | J29: ==IF(LEN(I29)>0,LEN(I29),"") -> 120 | K29: 改自Nurikabe+Sashigane | L29: sashigane+nurikabe | M29: Grant Fikes | N29: not in src | O29: PC
A30: oneroom | B30: 1 | C30: One Room One Door | D30: 单房门 | E30: ==HYPERLINK(_xlfn.CONCAT("pzplus.tck.mn/db?type=",A30,"&variant=no"),IF(D30<>0,D30,A30)) -> 单房门 | F30: 1 | G30: 涂黑I | H30: 颜色正交连通 | I30: 涂黑一些格子，使得涂黑的格子之间不相邻，且留白的格子连通成一个整体。每个区域中的留白格也需要连通成一个整体。数字表示此区域内涂黑格的个数。对于任意两个相邻的区域，不能有超过一对相邻留白格穿过它们相邻的边界。（也就是说，每两个“房间”至多有一扇“门”沟通）。 | J30: ==IF(LEN(I30)>0,LEN(I30),"") -> 128 | K30: COL译自Eric Fox | L30: / | M30: Nikoli vol. 169 | N30: 2019 | O30: puzzlink
A31: cts | B31: 1 | C31: Cross the Streams | D31: 过河 | E31: ==HYPERLINK(_xlfn.CONCAT("pzplus.tck.mn/db?type=",A31,"&variant=no"),IF(D31<>0,D31,A31)) -> 过河 | F31: 1 | G31: 涂黑I | H31: 颜色正交连通 | I31: 涂黑一些空格，使得所有涂黑的格子连通成一个整体，且没有全部涂黑的2×2结构。盘面外的数字依次表示此行或此列中每一段连续涂黑格的长度。问号可以表示任何单个提示数，而星号可以表示任何个连续的提示数（包括0个）。作为特例，一个单独的“0”表示此行或此列没有涂黑格。 | J31: ==IF(LEN(I31)>0,LEN(I31),"") -> 129 | K31: WPC2024IB | L31: / | M31: Grant Fikes | N31: 2010 | O31: PC
A32: coral | B32: 1 | C32: Coral | D32: 珊瑚 | E32: ==HYPERLINK(_xlfn.CONCAT("pzplus.tck.mn/db?type=",A32,"&variant=no"),IF(D32<>0,D32,A32)) -> 珊瑚 | F32: 1 | G32: 涂黑I | H32: 颜色正交连通 | I32: 涂黑一些格子，使得所有涂黑的格子连通成一个整体，且留白的格子连通到边界。涂黑的格子不能形成2×2的区域。盘面外的数字（如果有）表示此行或此列中每一段连续涂黑格的长度，数字之间无顺序要求。问号可以表示任何单个提示数。作为特例，一个单独的“0”表示此行或此列没有涂黑格。 | J32: ==IF(LEN(I32)>0,LEN(I32),"") -> 133 | K32: 怎苏昂 | L32: / | M32: Zoltán Horváth | N32: 2001 | O32: PC
A33: tapa | B33: 1 | C33: Tapa | D33: 土派回路 | E33: ==HYPERLINK(_xlfn.CONCAT("pzplus.tck.mn/db?type=",A33,"&variant=no"),IF(D33<>0,D33,A33)) -> 土派艺术 | F33: 1 | G33: 涂黑I | H33: 颜色正交连通 | I33: 涂黑一些空格，使得所有涂黑的格子连通成一个整体，且没有全部涂黑的2×2结构。格内一个或多个数字表示和此格接触的（至多）八格中所有连续涂黑格段的长度，但不限定顺序。作为特例，一个单独的“0”表示没有和此格接触的涂黑格，而一个单独的问号（格内没有其他问号或数字）也可以代表“0”。 | J33: ==IF(LEN(I33)>0,LEN(I33),"") -> 138 | K33: WPC2024IB | L33: Turkish Art Paint | M33: Serkan Yürekli | N33: 2007 | O33: PC
A34: nurimaze | B34: 1 | C34: Nurimaze | D34: 迷宫地图 | E34: ==HYPERLINK(_xlfn.CONCAT("pzplus.tck.mn/db?type=",A34,"&variant=no"),IF(D34<>0,D34,A34)) -> 迷宫地图 | F34: 1 | G34: 涂黑I | H34: 颜色正交连通 | I34: 把一些空格涂黑，使得没有全部涂黑或者全部留白的2×2结构，而且每个区域要么全部涂黑要么全部留白。所有留白格必须连通成一个整体且不成环。（也就是说，在任意两个留白格之间必须有唯一一条通过相邻留白格连接两者且不重复通过同一格的路径。）圆圈表示此格在S格到G格之间的唯一路径上，而三角形表示此格不在这条唯一路径上。 | J34: ==IF(LEN(I34)>0,LEN(I34),"") -> 154 | K34: WPC2024IB | L34: 塗り+maze | M34: Nikoli vol. 145 | N34: 2013 | O34: Nikoli
A35: norinori | B35: 1 | C35: Norinori | D35: 海苔 | E35: ==HYPERLINK(_xlfn.CONCAT("pzplus.tck.mn/db?type=",A35,"&variant=no"),IF(D35<>0,D35,A35)) -> 海苔 | F35: 2 | G35: 涂黑II | H35: 色块是海苔 | I35: 在每个区域内涂黑恰好两格，使得每一组涂黑的连通组恰好有两格。 | J35: ==IF(LEN(I35)>0,LEN(I35),"") -> 30 | K35: WPC2024IB | L35: ノリ(=海苔) | M35: Nikoli vol. 124 | N35: 2008 | O35: PC, Nikoli
A36: chocona | B36: 1 | C36: Chocona | D36: 巧克力 | E36: ==HYPERLINK(_xlfn.CONCAT("pzplus.tck.mn/db?type=",A36,"&variant=no"),IF(D36<>0,D36,A36)) -> 巧克力 | F36: 2 | G36: 涂黑II | H36: 色块是矩形 | I36: 涂黑一些格子，使得每组相连的涂黑格形状为长方形。数字表示该区域中涂黑的单元格数。 | J36: ==IF(LEN(I36)>0,LEN(I36),"") -> 40 | K36: COL译自puzzlink | L36: 缩略自 チョコに国境なし(choco无国界) | M36: Nikoli vol. 122 | N36: 2008 | O36: PC, Nikoli
A37: box | B37: 1 | C37: Box/Kakurasu | D37: 方阵和 | E37: ==HYPERLINK(_xlfn.CONCAT("pzplus.tck.mn/db?type=",A37,"&variant=no"),IF(D37<>0,D37,A37)) -> 方阵和 | F37: 2 | G37: 涂黑II | H37: 见Aquarium | I37: 涂黑一些空格，使得盘面外的数字等于此行或此列中涂黑格所在列号或行号（盘面外圆圈内的数字）的和。 | J37: ==IF(LEN(I37)>0,LEN(I37),"") -> 47 | K37: dodomos | L37: / | M37: Nikoli vol. 24 = 1988 | N37: 1989 | O37: PC, Nikoli
A38: tilepaint | B38: 1 | C38: Tilepaint | D38: 数瓦 | E38: ==HYPERLINK(_xlfn.CONCAT("pzplus.tck.mn/db?type=",A38,"&variant=no"),IF(D38<>0,D38,A38)) -> 数瓦 | F38: 2 | G38: 涂黑II | H38: 见Aquarium | I38: 涂黑一些空格，使得每个区域要么全部涂黑要么全部留白。盘面外的数字表示此行或此列内涂黑格的个数。 | J38: ==IF(LEN(I38)>0,LEN(I38),"") -> 47 | K38: dodomos | L38: tile+paint | M38: Nikoli vol. 53 | N38: 1995 | O38: PC, Nikoli
A39: cbanana | B39: 1 | C39: Choco Banana | D39: 巧克力香蕉 | E39: ==HYPERLINK(_xlfn.CONCAT("pzplus.tck.mn/db?type=",A39,"&variant=no"),IF(D39<>0,D39,A39)) -> 巧克力香蕉 | F39: 2 | G39: 涂黑II | H39: 黑白规则交替 | I39: 涂黑一些格子，使得每个涂黑的连通组都是长方形，而每个留白的连通组都不是长方形。数字表示其所在的涂黑或留白的连通组的面积。 | J39: ==IF(LEN(I39)>0,LEN(I39),"") -> 60 | K39: WPC2024IB | L39: / | M39: Nikoli
A40: bosnianroad | B40: 0.8 | C40: Bosnian Road | D40: 波斯尼亚路 | E40: ==HYPERLINK(_xlfn.CONCAT("pzplus.tck.mn/db?type=",A40,"&variant=no"),IF(D40<>0,D40,A40)) -> 波斯尼亚路 | F40: 2 | G40: 涂黑II | H40: 色块是一条路 | I40: 涂黑一些空格，使得所有涂黑的格子连通成一个不和自身接触的环。数字格不能涂黑。数字表示与此格接触的（至多）八格中的涂黑格个数。 | J40: ==IF(LEN(I40)>0,LEN(I40),"") -> 62 | K40: November, 有修改 | L40: / | M40: Dragan Tolomanoski | N40: not in src | O40: PC
...

Sheet 每日纸笔存档
B1: 日期 | D1: 类别 | E1: 链接 | F1: 作者 | G1: 时间1 | H1: 时间2 | I1: 文案
A2: 100 | B2: 45989 | C2: 五 | D2: 分区 | E2: https://pzplus.tck.mn/p?heteromino/8/8/j77777e7g7e7a7e7a7a7d7l | F2: xoned72 | G2: 1:15 | H2: 2:30 | I2: #每日谜题 (11.28) 今天是周五，每日谜题是一道【分区】题目—— Heteromino（三格拼版）：沿虚格线把盘面分成若干个三格骨牌，使得任意两个相邻的骨牌都不平移全等（也就是说，它们要么形状不同，要么朝向不同）。 题目链接：（本题作者xoned72） https://pzplus.tck.mn/p?heteromino/8/8/j77777e7g7e7a7e7a7a7d7l 在1:15内完成可以获得一束烟花🎉 在2:30内完成可以获得一朵玫瑰🌹 只要完成了就可以给自己一个赞！👍 今天是每日谜题复活以来的的第100期！
A3: 99 | B3: 45988 | C3: 四 | D3: 填写 | E3: https://pzplus.tck.mn/p?toichika/6/6/aljii4v7k47vz9 | F3: udoP_ | G3: 2:15 | H3: 4:30 | I3: #每日谜题 (11.27) 今天是周四，每日谜题是一道【填写】题目—— Toichika（山盟海誓）：在每个区域中放置一个箭头（↑ ↓ ← → 之一）。每个箭头都和另一个箭头配对，它们相互指向，它们之间不能有其他箭头。配对箭头所属的区域不能有公共边界。 题目链接：（本题作者udoP_） https://pzplus.tck.mn/p?toichika/6/6/aljii4v7k47vz9 在2:15内完成可以获得一束烟花🎉 在4:30内完成可以获得一朵玫瑰🌹 只要完成了就可以给自己一个赞！👍
A4: 98 | B4: 45987 | C4: 三 | D4: 涂黑III/放置 | E4: https://pzplus.tck.mn/p?martini/10/10/47774uftc6nuf4sss4fs6e09n6c6cti0ec7u3h0i0g0i2j.i3l0m.i0v.i.m0l.i2j0i0g0i.h3 | F4: djmathman | G4: 3:30 | H4: 7:00 | I4: #每日谜题 (11.26) 今天是周三，每日谜题是一道【涂黑III】题目—— Martini（马提尼）：在每个区域内涂黑至多一组连通的格子，使得不同区域内涂黑的连通组不相邻。所有涂黑格必须对角连通成一个整体。有黑圈的格子必须涂黑，有白圈的格子必须留白。白圈里的数字表示其所在的留白的连通组中的白圈个数，包括自身（这个连通组可能横跨多个区域）。 题目链接：（本题作者djmathman） https://pzplus.tck.mn/p?martini/10/10/47774uftc6nuf4sss4fs6e09n6c6cti0ec7u3h0i0g0i2j.i3l0m.i0v.i.m0l.i2j0i0g0i.h3 在3:30内完成可以获得一束烟花🎉 在7:00内完成可以获得一朵玫瑰🌹 只要完成了就可以给自己一个赞！👍 词源：Cocktail Lamp 的派生, 黑圈形似橄榄
A5: 97 | B5: 45986 | C5: 二 | D5: 涂黑II | E5: https://pzplus.tck.mn/p?box/6/6/7a5f7dbj7d98 | F5: 墨矾 | G5: 1:30 | H5: 3:00 | I5: #每日谜题 (11.25) 今天是周二，每日谜题是一道【涂黑II】题目—— Box/Kakurasu（方阵和）：涂黑一些空格，使得盘面外的数字等于此行或此列中涂黑格所在列号或行号（盘面外圆圈内的数字）的和。 题目链接：（本题作者墨矾） https://pzplus.tck.mn/p?box/6/6/7a5f7dbj7d98 在1:30内完成可以获得一束烟花🎉 在3:00内完成可以获得一朵玫瑰🌹 只要完成了就可以给自己一个赞！👍
A6: 96 | B6: 45985 | C6: 一 | D6: 涂黑I | E6: https://pzplus.tck.mn/p?cave/9/9/g2g2h3p32g2i3l6i3o5i6l5i4g45p5h4g4g | F6: Matej Uher from 22nd 24HPC | G6: 3:00 | H6: 6:00 | I6: #每日谜题 (11.24) 今天是周一，每日谜题是一道【涂黑I】题目—— Cave（山洞）：涂黑一些格子，使得所有涂黑的格子都能沿涂黑格横竖连通到盘面边界，且留白的格子连通成一个整体。数字必须在留白格里，并表示此格横竖能够直接连接到且不被涂黑格阻挡的留白格个数，包括此格本身。 题目链接：（本题作者Matej Uher from 22nd 24HPC） https://pzplus.tck.mn/p?cave/9/9/g2g2h3p32g2i3l6i3o5i6l5i4g45p5h4g4g 在3:00内完成可以获得一束烟花🎉 在6:00内完成可以获得一朵玫瑰🌹 只要完成了就可以给自己一个赞！👍
A7: 95 | B7: 45984 | C7: 日 | D7: 回路II/路径II | E7: https://pzprxs.vercel.app/p?kurarin/10/10/pcg2g8ch8g1o1h8g8j1n1icg8h1q2h4k22l8g22h8k22lcg2q3i8g4h3n3k8g8g3o3h8h482h4p | F7: dodomos | G7: 3:00 | H7: 6:00 | I7: #每日谜题 (11.23) 今天是周日，每日谜题是一道【回路II】题目—— Kurarin（比例回路）：在盘面内涂黑一些格子，使得留白的格子形成一条横平竖直不交叉的回路。盘面内的点提示了周围两格或者四格中涂黑格和留白格哪种更多：白色表示留白格更多，黑色表示涂黑格更多，灰色表示涂黑格和留白格一样多。 题目链接：（本题作者dodomos） https://pzprxs.vercel.app/p?kurarin/10/10/pcg2g8ch8g1o1h8g8j1n1icg8h1q2h4k22l8g22h8k22lcg2q3i8g4h3n3k8g8g3o3h8h482h4p 在3:00内完成可以获得一束烟花🎉 在6:00内完成可以获得一朵玫瑰🌹 只要完成了就可以给自己一个赞！👍 提示：pzprxs的访问可能需要科学上网。
A8: 94 | B8: 45983 | C8: 六 | D8: 回路I/路径I | E8: https://pzplus.tck.mn/p?nagare/10/10/d9a4d9d5a7b4a9g5e7e2a5c76c5g6e5g8d6a5d8d3a8d | F8: niwabee10 | G8: 3:00 | H8: 6:00 | I8: #每日谜题 (11.22) 今天是周六，每日谜题是一道【回路I】题目—— Nagereru-Loop（吹风机回路）：画一条横平竖直地经过一些白格中心且不和自身交叉的有向回路。回路不能经过黑格。回路必须按箭头方向穿过所有带黑色箭头的白格，不能在格内转弯。带白色箭头的黑格代表风扇，会沿箭头方向吹风直到下一个黑格为止。在这些受风影响的白格中，回路不得逆风前进，并且一旦进入受风影响的格子，必须立即按照风向转向，前进至少一格。 题目链接：（本题作者niwabee10） https://pzplus.tck.mn/p?nagare/10/10/d9a4d9d5a7b4a9g5e7e2a5c76c5g6e5g8d6a5d8d3a8d 在3:00内完成可以获得一束烟花🎉 在6:00内完成可以获得一朵玫瑰🌹 只要完成了就可以给自己一个赞！👍
A9: 93 | B9: 45982 | C9: 五 | D9: 分区 | E9: https://pzplus.tck.mn/p?kramma/c/7/7/b026c6aib232il10i | F9: Andrey Bogdanov | G9: 1:15 | H9: 2:30 | I9: #每日谜题 (11.21) 今天是周五，每日谜题是一道【分区】题目—— KaitoRamma（快刀乱麻）：沿虚格线把盘面分成若干个区域，其中每一条分割线必须完全横平竖直，且两端都在盘面边界上。每个区域至少包含一个圆圈，而且所有同一区域的圆圈必须同色。 题目链接：（本题作者Andrey Bogdanov） https://pzplus.tck.mn/p?kramma/c/7/7/b026c6aib232il10i 在1:15内完成可以获得一束烟花🎉 在2:30内完成可以获得一朵玫瑰🌹 只要完成了就可以给自己一个赞！👍
A10: 92 | B10: 45981 | C10: 四 | D10: 填写 | E10: https://pzplus.tck.mn/p?goishi/9/9/vvnf5cnbtrnqvrvvg | F10: パリパリバー教団 | G10: 1:00 | H10: 2:00 | I10: #每日谜题 (11.20) 今天是周四，每日谜题是一道【填写】题目—— Goishi（捡棋子）：从1开始在每颗棋子上标数，代表捡走棋子的顺序。连续两个被捡走的棋子必须同行或同列，且中间不能有未捡的棋子。捡棋子的过程中不允许180°掉头。 题目链接：（本题作者パリパリバー教団） https://pzplus.tck.mn/p?goishi/9/9/vvnf5cnbtrnqvrvvg 在1:00内完成可以获得一束烟花🎉 在2:00内完成可以获得一朵玫瑰🌹 只要完成了就可以给自己一个赞！👍
A11: 91 | B11: 45980 | C11: 三 | D11: 涂黑III/放置 | E11: https://pzplus.tck.mn/p?cocktail/10/10/gi94a8khp3i70e0s1oc0vu00vu00ue00uf0044444044234444 | F11: nisimuku_sen | G11: 2:00 | H11: 4:00 | I11: #每日谜题 (11.19) 今天是周三，每日谜题是一道【涂黑III】题目—— Cocktail Lamp（鸡尾酒灯）：在每个区域内涂黑至多一组连通的格子，使得不同区域内涂黑的连通组不相邻。数字表示区域内涂黑格的个数。所有涂黑格必须对角连通成一个整体。不能有全部涂黑的2×2结构。 题目链接：（本题作者nisimuku_sen） https://pzplus.tck.mn/p?cocktail/10/10/gi94a8khp3i70e0s1oc0vu00vu00ue00uf0044444044234444 在2:00内完成可以获得一束烟花🎉 在4:00内完成可以获得一朵玫瑰🌹 只要完成了就可以给自己一个赞！👍
A12: 90 | B12: 45979 | C12: 二 | D12: 涂黑II | E12: https://pzplus.tck.mn/p?lookair/10/10/1d3x1g4m0a1b1e3c1h2m2h2 | F12: RS_Puzzling | G12: 3:30 | H12: 7:00 | I12: #每日谜题 (11.18) 今天是周二，每日谜题是一道【涂黑II】题目—— Look-Air（观云）：涂黑一些格子，使得每一组涂黑的连通组都是正方形。在每行和每列内，任意两个仅由（至少一个）留白格分隔的涂黑格不能在两个全等的正方形里（也就是说任意两个全等的正方形都不能在对方的“视线”内）。数字表示此格以及与其相邻的（至多）四格中涂黑格的个数。 题目链接：（本题作者RS_Puzzling） https://pzplus.tck.mn/p?lookair/10/10/1d3x1g4m0a1b1e3c1h2m2h2 在3:30内完成可以获得一束烟花🎉 在7:00内完成可以获得一朵玫瑰🌹 只要完成了就可以给自己一个赞！👍
A13: 89 | B13: 45978 | C13: 一 | D13: 涂黑I | E13: https://pzplus.tck.mn/p?guidearrow/8/8/11pepcpehcpdm | F13: TealsPuzzles | G13: 2:00 | H13: 4:00 | I13: #每日谜题 (11.17) 今天是周一，每日谜题是一道【涂黑I】题目—— Guide Arrow（指引箭头）：涂黑一些格子，使得涂黑的格子之间不相邻，且留白的格子连通成一个整体。留白格不能形成回路（包括2×2结构）。箭头表示从这一格出发，在不经过涂黑格也不倒退的情况下，能够走到星星的路径的唯一方向。 题目链接：（本题作者TealsPuzzles） https://pzplus.tck.mn/p?guidearrow/8/8/11pepcpehcpdm 在2:00内完成可以获得一束烟花🎉 在4:00内完成可以获得一朵玫瑰🌹 只要完成了就可以给自己一个赞！👍
... A87: 15 | B87: 45904 | C87: 四 | D87: 填写 | E87: https://pzplus.tck.mn/p?makaro/8/8/5evelrlbnungu9vdetdurdh0oejejck2idjbi2kbjejbo | F87: トクナキラ | G87: 2:30 | H87: 5:00 | I87: #每日谜题 (9.4) 今天是周四，每日谜题是一道【填写】题目—— Makaro（极大箭头）：在每个空格里填一个数，使得每个区域里包含数字1~N，其中N是这个区域的总格数。相邻的格子里不能填相同的数字。黑格里的箭头必须指向所有与此格相邻的数字中唯一最大的一个。 题目链接：（本题作者トクナキラ） https://pzplus.tck.mn/p?makaro/8/8/5evelrlbnungu9vdetdurdh0oejejck2idjbi2kbjejbo 在2:30内完成可以获得一束烟花🎉 在5:00内完成可以获得一朵玫瑰🌹 只要完成了就可以给自己一个赞！👍 触屏用户建议勾选Input numbers by panel方便填写
A88: 14.02 | B88: 45903 | C88: 三 | D88: 涂黑III/放置
A89: 14.01 | B89: 45902 | C89: 二 | D89: 涂黑II
A90: 14 | B90: 45901 | C90: 一 | D90: 涂黑I | E90: https://pzplus.tck.mn/p?creek/10/10/icm22167cg87do7dg8ckcg77cg38ck8166dibh77c88cp | F90: tibisukemaru | G90: 2:30 | H90: 5:00 | I90: #每日谜题 (9.1) 今天是周一，每日谜题是一道【涂黑I】题目—— Creek（溪流）：涂黑一些格子，使得留白的格子连通成一个整体。圆圈里的数字表示接触此顶点的涂黑格数。 题目链接：（本题作者tibisukemaru） https://pzplus.tck.mn/p?creek/10/10/icm22167cg87do7dg8ckcg77cg38ck8166dibh77c88cp 在2:30内完成可以获得一束烟花🎉 在5:00内完成可以获得一朵玫瑰🌹 只要完成了就可以给自己一个赞！👍
A91: 13 | B91: 45900 | C91: 日 | D91: 回路II/路径II | E91: https://puzz.link/p?simpleloop/v:/10/10/000064040000005k0000 | F91: Eric Fox | G91: 2:15 | H91: 4:30 | I91: #每日谜题 (8.31) 今天是周日，每日谜题是一道【回路II】题目—— Simpleloop (Short)（简单回路（短线段））：画一条横平竖直地经过所有空格中心且不和自身交叉的回路。 【⚠️变种题型规则：回路不能有线段长度超过两个单元格边长。】 题目链接：（本题作者Eric Fox） https://puzz.link/p?simpleloop/v:/10/10/000064040000005k0000 在2:15内完成可以获得一束烟花🎉 在4:30内完成可以获得一朵玫瑰🌹 只要完成了就可以给自己一个赞！👍
A92: 12 | B92: 45899 | C92: 六 | D92: 回路I/路径I | E92: https://pzplus.tck.mn/p?castle/10/10/f00.g231g141d141b022d042g241d212b112d141g042d022b241d241g131g00.f | F92: brokensign | G92: 3:00 | H92: 6:00 | I92: #每日谜题 (8.30) 今天是周六，每日谜题是一道【回路I】题目—— Castle Wall（城堡墙）：画一条横平竖直地经过一些空格中心且不和自身交叉的回路。黑格或白格内带箭头的数字表示从此格开始按照这个方向的所有直线段的总长度。有这些提示数的黑格必须在回路外，白格必须在回路内。 题目链接：（本题作者brokensign） https://pzplus.tck.mn/p?castle/10/10/f00.g231g141d141b022d042g241d212b112d141g042d022b241d241g131g00.f 在3:00内完成可以获得一束烟花🎉 在6:00内完成可以获得一朵玫瑰🌹 只要完成了就可以给自己一个赞！👍
A93: 11 | B93: 45898 | C93: 五 | D93: 分区 | E93: https://pzplus.tck.mn/p?fivecells/10/10/2b23n1a2c11a2a13f1m1c1g1b2c33b2b22e3e2a2f | F93: bachelor seal | G93: 3:00 | H93: 6:00 | I93: #每日谜题 (8.29) 今天是周五，每日谜题是一道【分区】题目—— FiveCells（五格分区）：沿虚格线把盘面分成若干个五格骨牌。数字表示此格中是区域边界的边数。 题目链接：（本题作者bachelor seal） https://pzplus.tck.mn/p?fivecells/10/10/2b23n1a2c11a2a13f1m1c1g1b2c33b2b22e3e2a2f 在3:00内完成可以获得一束烟花🎉 在6:00内完成可以获得一朵玫瑰🌹 只要完成了就可以给自己一个赞！👍
A94: 10 | B94: 45897 | C94: 四 | D94: 填写 | E94: https://pzplus.tck.mn/p?putteria/10/10/65d7ku76djcsktimkjdu5c3mrrmib65tsi6kzzzzz | F94: 伊香湾 | G94: 5:30 | H94: 11:00 | I94: #每日谜题 (8.28) 今天是周四，每日谜题是一道【填写】题目—— Putteria：给每个粗线围成区域的其中一格填上等于该区域面积的数字。填有数字的格子不能有公共边，每行和每列不能有重复数字。 题目链接：（本题作者伊香湾） https://pzplus.tck.mn/p?putteria/10/10/65d7ku76djcsktimkjdu5c3mrrmib65tsi6kzzzzz 在5:30内完成可以获得一束烟花🎉 在11:00内完成可以获得一朵玫瑰🌹 只要完成了就可以给自己一个赞！👍
A95: 9 | B95: 45896 | C95: 三 | D95: 涂黑III/放置 | E95: https://pzplus.tck.mn/p?starbattle/10/10/2/10rhmcugkogd6dhn124806r6e98omedacg2c | F95: djmathman | G95: 5:00 | H95: 10:00 | I95: #每日谜题 (8.27) 今天是周三，每日谜题是一道【放置】题目—— Star Battle（星战）：在一些格子内放置一颗星，使得每行、列、区域内的星数等于盘面外给出的数字。任意两颗星不能放在互相接触的格子内。 题目链接：（本题作者djmathman） https://pzplus.tck.mn/p?starbattle/10/10/2/10rhmcugkogd6dhn124806r6e98omedacg2c 在5:00内完成可以获得一束烟花🎉 在10:00内完成可以获得一朵玫瑰🌹 只要完成了就可以给自己一个赞！👍
A96: 8 | B96: 45895 | C96: 二 | D96: 涂黑II | E96: https://pzplus.tck.mn/p?norinori/10/10/1c6nlmpdjhc1419951u2f2iv0uf5vqvmvt5u | F96: bachelor seal | G96: 3:15 | H96: 6:30 | I96: #每日谜题 (8.26) 今天是周二，每日谜题是一道【涂黑II】题目—— Norinori（海苔）：在每个区域内涂黑恰好两格，使得每一组涂黑的连通组恰好有两格。 题目链接：（本题作者bachelor seal） https://pzplus.tck.mn/p?norinori/10/10/1c6nlmpdjhc1419951u2f2iv0uf5vqvmvt5u 在3:15内完成可以获得一束烟花🎉 在6:30内完成可以获得一朵玫瑰🌹 只要完成了就可以给自己一个赞！👍
A97: 7 | B97: 45894 | C97: 一 | D97: 涂黑I | E97: https://pzplus.tck.mn/p?nurikabe/10/10/s8p6l6j4g5g7i3zi3zk7k | F97: tibisukemaru | G97: 1:15 | H97: 2:30 | I97: #每日谜题 (8.25) 今天是周一，每日谜题是一道【涂黑I】题目—— Nurikabe（数墙）：涂黑一些空格，使得所有涂黑的格子连通成一个整体，且没有全部涂黑的2×2结构。每一组连通的留白格必须恰好包含一个数字。数字表示其所在的留白的连通组格数。 题目链接：（本题作者tibisukemaru） https://pzplus.tck.mn/p?nurikabe/10/10/s8p6l6j4g5g7i3zi3zk7k 在1:15内完成可以获得一束烟花🎉 在3:30内完成可以获得一朵玫瑰🌹 只要完成了就可以给自己一个赞！👍
A98: 6 | B98: 45893 | C98: 日 | D98: 回路II/路径II | E98: https://pzplus.tck.mn/p?koburin/b/10/10/.kau.tcbrccrcuci./ | F98: @bakpao_puz | G98: 2:30 | H98: 4:30 | I98: #每日谜题 (8.24) 今天是周日，每日谜题是一道【回路II】题目—— Koburin（仙人指邻）：画一条横平竖直地经过一些空格中心且不和自身交叉的回路，并把未经过的空格涂黑。涂黑的格子不能相邻。数字表示和此格相邻的黑格数。 题目链接：（本题作者@bakpao_puz） https://pzplus.tck.mn/p?koburin/b/10/10/.kau.tcbrccrcuci./ 在2:30内完成可以获得一束烟花🎉 在4:30内完成可以获得一朵玫瑰🌹 只要完成了就可以给自己一个赞！👍
A99: 5 | B99: 45892 | C99: 六 | D99: 回路I/路径I | E99: https://pzplus.tck.mn/p?slalom/d/17/17/e14271331417241418161516251526271415251615192f13341313331314152j151314141333331718241624171314261428172814133427261a15131713331524171526252c1414152iu2b4c3c4d3dg1bzk/0 | F99: bachelor seal | G99: 3:00 | H99: 6:00 | I99: #每日谜题 (8.23) 今天是周六，每日谜题是一道【回路I】题目—— Slalom（巡行通关）：画一条横平竖直地经过一些白格中心且不和自身交叉的有向回路，其中起点和终点都在圆圈的格子。回路必须直行通过每个用粗虚线标记的“关卡”恰好一次。黑格里带数字的箭头表示回路从圆圈出发后经过其指向的关卡的次序。盘面中的总关卡数在圈内给出。 题目链接：（本题作者bachelor seal） https://pzplus.tck.mn/p?slalom/d/17/17/e14271331417241418161516251526271415251615192f13341313331314152j151314141333331718241624171314261428172814133427261a15131713331524171526252c1414152iu2b4c3c4d3dg1bzk/0 在3:30内完成可以获得一束烟花🎉 在7:00内完成可以获得一朵玫瑰🌹 只要完成了就可以给自己一个赞！👍
A100: 4 | B100: 45891 | C100: 五 | D100: 分区 | E100: https://pzplus.tck.mn/p?dbchoco/10/10/0usususu0000f7f7f7f0g4w6i4s2h1zp5r6q3i | F100: Yu-ri | G100: 2:15 | H100: 4:30 | I100: #每日谜题 (8.22) 今天是周五，每日谜题是一道【分区】题目—— Double Choco（双巧克力）：沿虚格线把盘面分成若干个区域，使得每个区域里恰有一组连通的灰格和一组连通的白格，而且两组格子相邻且全等。数字表示其所在区域中一个连通组的面积（也就是区域总面积的一半）。 题目链接：（本题作者Yu-ri） https://pzplus.tck.mn/p?dbchoco/10/10/0usususu0000f7f7f7f0g4w6i4s2h1zp5r6q3i 在2:15内完成可以获得一束烟花🎉 在4:30内完成可以获得一朵玫瑰🌹 只要完成了就可以给自己一个赞！👍
A101: 3 | B101: 45890 | C101: 四 | D101: 填写 | E101: https://pzplus.tck.mn/p?wagiri/7/7/u62em3dido6cg2cmg1a1l2j2o | F101: bachelor seal | G101: 1:45 | H101: 3:30 | I101: #每日谜题 (8.21) 今天是周四，每日谜题是一道【填写】题目—— Wagiri（斜线(环和切)）：在每个方格中画一条对角线，使得圈中数字等于从该顶点引出的斜线数。标有“轮”的格子必须位于至少一个环上，标有“切”的格子不能位于环上。 题目链接：（本题作者bachelor seal） https://pzplus.tck.mn/p?wagiri/7/7/u62em3dido6cg2cmg1a1l2j2o 在1:45内完成可以获得一束烟花🎉 在3:30内完成可以获得一朵玫瑰🌹 只要完成了就可以给自己一个赞！👍
... A103: 1 | B103: 45888 | C103: 二 | D103: 涂黑II | E103: https://pzplus.tck.mn/p?lightshadow/7/7/k1haq11g1gagaaq1hak | F103: ihnnpuzzles | G103: 2:00 | H103: 4:00 | I103: #每日谜题 (8.19) Midloop（中点回路）：画一条横平竖直地经过一些格子中心且不和自身交叉的回路。回路必须笔直经过所有黑点，而且每个黑点必须是其所在的直线段的中点。 题目链接：（本题作者bachelor seal） https://pzplus.tck.mn/p?midloop/10/10/jfzpdfzs7fgfibfwfgfzzw7fzzi9ffzkfvfo 在2:30内完成可以获得一束烟花🎉 在4:00内完成可以获得一朵玫瑰🌹 只要完成了就可以给自己一个赞！👍 好久不见，每日谜题回来啦！
